Workbook

Sheet README
A1: KYC / AML Compliance Operations Simulation
A2: An Excel-only (formula-driven, no macros, no code) portfolio project for a Client Data / KYC Analyst role.
A4: IMPORTANT
A5: All clients, transactions and amounts are SYNTHETIC (invented). Thresholds, country scores and rules are illustrative and not legal advice. This is a self-built simulation to show method and skills, not real work history.
A7: PURPOSE
A8: Simulates the day-to-day work of a KYC quality reviewer: check client records for completeness and errors, monitor transactions against red flags, assess CTR obligations, reconcile two data sources, escalate with a written risk summary, and resolve client-facing issues within SLA.
A10: SHEET GUIDE
A11: Dashboard | B11: KPIs and charts across every process, all formula-driven.
A12: Assumptions | B12: Thresholds, risk-scoring tables, review cycles and SLAs (blue = editable inputs). Change a value and every sheet recalculates.
A13: Client_Master | B13: KYC records for 40 clients + automated checks: document completeness, risk score vs assigned rating, periodic review due dates, duplicates, date logic and blank fields.
A14: Transactions | B14: Cash and wire activity with helper columns: near-threshold flag, daily cash aggregation, country risk, KYC status.
A15: CTR_Log | B15: Daily cash aggregation per client and direction, CTR required test, filing deadline and timeliness tracking.
A16: Alert_Monitoring | B16: Six scenario rules (R1-R6) per client, with an ESCALATE / Analyst Review / No Action disposition.
A17: Escalation_Matrix | B17: Escalation levels, owners, SLAs and documentation requirements.
A18: Escalation_Log | B18: 10 cases with analyst-written risk summaries, SLA tracking and outcomes.
A19: Recon_Client | B19: CRM vs Core Banking client data reconciliation (name, country, rating, missing records, active accounts with incomplete KYC).
A20: Recon_Txn | B20: Ledger vs bank statement reconciliation with a control-total proof that every difference is explained.
A21: Customer_Issues | B21: 14 client/internal tickets with priority, SLA tracking and resolution notes.
A22: Src_CoreBanking / Src_BankStatement | B22: Source extracts used by the reconciliations.
A24: COLOUR LEGEND
A25: Navy header | B25: Raw data / manual input columns (safe to edit).
A26: Grey header | B26: Formula columns - do not overwrite.
A27: Red / amber / green cells | B27: Conditional formatting: red = exception or breach, amber = attention, green = OK.
A29: PLANTED SCENARIOS (what a reviewer should find)
A30: CTR aggregation | B30: C005: two same-day deposits ($6,200 + $5,100) aggregate above $10,000. C012: single $14,500 deposit. C008: three large deposits, one CTR not filed by the deadline.
A31: Structuring | B31: C019: four deposits of $9,200-$9,800 in five days, each under the threshold.
A32: High-risk jurisdiction | B32: C027: $105,000 wired to Myanmar; client under-rated.
A33: PEP / pass-through | B33: C015: PEP with $240,000 of wires. C022: $250,000 in, $246,500 out within three days.
A34: Sanctions / onboarding | B34: C036: unresolved potential match. C038: wire received before KYC completion.
A35: Data breaks | B35: Name, country and rating mismatches; client missing from core banking; account with no KYC record (C041); duplicate client record; date logic error; 3 amount breaks, 2 missing and 1 duplicate in the bank statement.
A37: HOW TO USE
A38: 1 | B38: Open Dashboard for the overall picture, then follow each exception to its sheet.
A39: 2 | B39: Change a threshold in Assumptions (e.g. CTR threshold) and watch CTR flags, alerts and the dashboard update.
A40: 3 | B40: Add a row to Client_Master or Transactions and copy the grey formula cells down to test a new case.

Sheet Dashboard
A1: KYC / AML Compliance Operations - Dashboard
A2: ="As of "&TEXT(Assumptions!B4,"dd-mmm-yyyy")&" | Synthetic data - for portfolio demonstration only" -> As of 26-Oct-2026 | Synthetic data - for portfolio demonstration only
A4: 1. KYC FILE HEALTH
A5: Total client records | B5: =COUNTA(Client_Master!A2:A41) -> 40
A6: Complete KYC files | B6: =COUNTIF(Client_Master!R2:R41,"Complete") -> 35
A7: % files complete | B7: =B6/B5 -> 0.875
A8: Records missing one or more documents | B8: =COUNTIF(Client_Master!P2:P41,">0") -> 4
A9: Periodic reviews overdue | B9: =COUNTIF(Client_Master!AA2:AA41,"Overdue") -> 6
A10: Periodic reviews due within 60 days | B10: =COUNTIF(Client_Master!AA2:AA41,"Due within 60 days") -> 2
A11: Risk rating mismatches (under/over-rated) | B11: =COUNTIF(Client_Master!X2:X41,"Under-rated")+COUNTIF(Client_Master!X2:X41,"Over-rated") -> 4
A12: PEP clients | B12: =COUNTIF(Client_Master!N2:N41,"Y") -> 2
A13: Records with at least one DQ exception | B13: =COUNTIF(Client_Master!AE2:AE41,">0") -> 16
A14: Transactions on accounts with incomplete / no KYC | B14: =COUNTIF(Transactions!O2:O114,"<>Complete") -> 14
A16: 2. RISK RATING DISTRIBUTION (assigned)
A17: High | B17: =COUNTIF(Client_Master!H2:H41,"High") -> 2
A18: Medium | B18: =COUNTIF(Client_Master!H2:H41,"Medium") -> 7
A19: Low | B19: =COUNTIF(Client_Master!H2:H41,"Low") -> 31
A21: 3. CTR REPORTING
A22: Client-days requiring a CTR | B22: =COUNTIF(CTR_Log!F2:F21,"YES") -> 5
A23: Total cash value covered by CTRs (USD) | B23: =SUMIFS(CTR_Log!D2:D21,CTR_Log!F2:F21,"YES")+SUMIFS(CTR_Log!E2:E21,CTR_Log!F2:F21,"YES") -> 110800
A24: Filed on time | B24: =COUNTIF(CTR_Log!L2:L21,"On time") -> 3
A25: Pending - within deadline | B25: =COUNTIF(CTR_Log!L2:L21,"Pending*") -> 1
A26: Late / not filed (exceptions) | B26: =COUNTIF(CTR_Log!L2:L21,"LATE*")+COUNTIF(CTR_Log!L2:L21,"Late") -> 1
A27: Near-threshold cash transactions (structuring watch) | B27: =COUNTIF(Transactions!K2:K114,"Y") -> 4
A29: 4. TRANSACTION MONITORING
A30: Clients monitored | B30: =COUNTA(Alert_Monitoring!A2:A41) -> 40
A31: Disposition: ESCALATE | B31: =COUNTIF(Alert_Monitoring!R2:R41,"ESCALATE") -> 4
A32: Disposition: Analyst Review | B32: =COUNTIF(Alert_Monitoring!R2:R41,"Analyst Review") -> 2
A33: Disposition: No Action | B33: =COUNTIF(Alert_Monitoring!R2:R41,"No Action") -> 34
A35: 5. ESCALATIONS
A36: Cases logged | B36: =COUNTA(Escalation_Log!A2:A11) -> 10
A37: Open cases | B37: =COUNTIF(Escalation_Log!K2:K11,"Open") -> 8
A38: Closed cases | B38: =COUNTIF(Escalation_Log!K2:K11,"Closed") -> 2
A39: SLA breached | B39: =COUNTIF(Escalation_Log!M2:M11,"SLA Breached") -> 1
A41: 6. DATA RECONCILIATION
A42: Client recon: reconciled | B42: =COUNTIF(Recon_Client!M2:M42,"Reconciled") -> 35
A43: Client recon: field breaks | B43: =COUNTIF(Recon_Client!M2:M42,"Break*") -> 4
A44: Client recon: missing in CRM / Core | B44: =COUNTIF(Recon_Client!M2:M42,"Missing*") -> 2
A45: Active accounts with incomplete / no KYC | B45: =COUNTIF(Recon_Client!N2:N42,"Active*") -> 6
A46: Txn recon: Matched | B46: =COUNTIF(Recon_Txn!E2:E115,"Matched") -> 107
...

Sheet Assumptions
A1: Assumptions & Reference Tables
A2: Blue values are inputs - change them and every sheet recalculates. All thresholds are ILLUSTRATIVE; replace with your firm/regulator values.
A3: Parameter | B3: Value | C3: Note / Basis
A4: As-of (review) date | B4: 46321 | C4: Fixed date so results are reproducible. Replace with =TODAY() for live use.
A5: CTR threshold (USD) | B5: 10000 | C5: US BSA: cash transactions MORE than $10,000 in one business day, aggregated per person, per direction. Edit for other regimes.
A6: Structuring band - lower bound (USD) | B6: 8000 | C6: Cash amounts from this value up to the CTR threshold are treated as "near-threshold".
A7: Min near-threshold cash txns to alert | B7: 3 | C7: Rule R1: number of near-threshold cash transactions in the window.
A8: Cash vs profile multiple | B8: 2 | C8: Rule R2: alert when actual cash > expected cash x this multiple.
A9: Monitoring window (months) | B9: 2 | C9: Transactions cover Sep-Oct 2026. Expected cash is scaled by this.
A10: CTR filing deadline (calendar days) | B10: 15 | C10: US FinCEN CTR: file within 15 calendar days of the transaction.
A11: PEP activity review threshold (USD) | B11: 100000 | C11: Rule R4: PEP with total wire value at/above this is escalated.
A12: Pass-through tolerance (+/-) | B12: 0.05 | C12: Rule R5: outbound within +/-5% of inbound.
A13: Pass-through minimum value (USD) | B13: 100000 | C13: Rule R5: both inbound and outbound wires at least this size.
A14: High risk - minimum score | B14: 6 | C14: Score >= this = High.
A15: Medium risk - minimum score | B15: 3 | C15: Score >= this (and below High) = Medium.
A16: PEP score weight | B16: 3 | C16: Added to risk score when client is a PEP.
A19: Reference tables (risk scoring, review cycles, SLAs)
A21: Country | B21: Risk Score (0-3) | C21: Basis (illustrative - not an official list) | E21: Industry | F21: Risk Score | H21: Entity Type | I21: Risk Score | K21: Risk Rating | L21: Review Cycle (Years) | N21: Issue Priority | O21: SLA (business days)
A22: United States | B22: 0 | C22: Lower risk | E22: Software/IT | F22: 0 | H22: Corporate | I22: 0 | K22: High | L22: 1 | N22: High | O22: 2
A23: United Kingdom | B23: 0 | C23: Lower risk | E23: Manufacturing | F23: 0 | H23: Individual | I23: 0 | K23: Medium | L23: 2 | N23: Medium | O23: 5
A24: India | B24: 0 | C24: Lower risk | E24: Healthcare | F24: 0 | H24: Partnership | I24: 1 | K24: Low | L24: 3 | N24: Low | O24: 10
A25: Singapore | B25: 0 | C25: Lower risk | E25: Consulting | F25: 1 | H25: Trust | I25: 1
A26: Germany | B26: 0 | C26: Lower risk | E26: Retail | F26: 1
A27: Switzerland | B27: 0 | C27: Lower risk | E27: Logistics & Shipping | F27: 1
A28: Japan | B28: 0 | C28: Lower risk | E28: Real Estate | F28: 2
A29: Canada | B29: 0 | C29: Lower risk | E29: Import/Export Trading | F29: 2
A30: Hong Kong | B30: 1 | C30: Medium - monitor | E30: Restaurants & Hospitality | F30: 2
A31: United Arab Emirates | B31: 1 | C31: Medium - monitor | E31: Charity/NGO | F31: 2
A32: Cyprus | B32: 1 | C32: Medium - monitor | E32: Used Vehicle Dealers | F32: 2
A33: Turkey | B33: 1 | C33: Medium - monitor | E33: Jewelry & Precious Metals | F33: 3
A34: Panama | B34: 2 | C34: Elevated risk | E34: Money Services Business | F34: 3
A35: Cayman Islands | B35: 2 | C35: Elevated risk | E35: Casinos & Gaming | F35: 3
A36: Nigeria | B36: 2 | C36: Elevated risk
A37: Myanmar | B37: 3 | C37: High risk / call for action
A38: Iran | B38: 3 | C38: High risk / call for action
A39: North Korea | B39: 3 | C39: High risk / call for action
A41: Risk score = Country + Industry + Entity type + (PEP weight if PEP). Rating: High / Medium / Low per thresholds above.

Sheet Client_Master
A1: Client ID | B1: Legal Name | C1: Entity Type | D1: Country | E1: Industry | F1: Onboarding Date | G1: Last KYC Review | H1: Assigned Risk Rating | I1: CIP Verified (Y/N) | J1: UBO Identified (Y/N) | K1: Address Proof (Y/N) | L1: Source of Funds (Y/N) | M1: Sanctions Screening | N1: PEP (Y/N) | O1: Expected Monthly Cash (USD) | P1: Docs Missing (of 4) | Q1: Blank Mandatory Fields | R1: File Status | S1: Country Score | T1: Industry Score | U1: Entity Score | V1: Risk Score | W1: Calculated Rating | X1: Rating Check | Y1: Review Cycle (Yrs) | Z1: Next Review Due | AA1: Review Status | AB1: Days Overdue | AC1: Duplicate Check | AD1: Date Logic Check | AE1: DQ Exception Count
A2: C001 | B2: Aurora Software Solutions Pvt Ltd | C2: Corporate | D2: India | E2: Software/IT | F2: 45326 | G2: 46160 | H2: Low | I2: Y | J2: Y | K2: Y | L2: Y | M2: Clear | N2: N | O2: 0 | P2: =4-COUNTIF(I2:L2,"Y") -> 0 | Q2: =COUNTBLANK(A2:O2) -> 0 | R2: =IF(P2>0,"Incomplete - Docs",IF(M2<>"Clear","Incomplete - Screening","Complete")) -> Complete | S2: =IFERROR(INDEX(Assumptions!$B$22:$B$39,MATCH(D2,Assumptions!$A$22:$A$39,0)),0) -> 0 | T2: =IFERROR(INDEX(Assumptions!$F$22:$F$35,MATCH(E2,Assumptions!$E$22:$E$35,0)),0) -> 0 | U2: =IFERROR(INDEX(Assumptions!$I$22:$I$25,MATCH(C2,Assumptions!$H$22:$H$25,0)),0) -> 0 | V2: =S2+T2+U2+IF(N2="Y",Assumptions!$B$16,0) -> 0 | W2: =IF(V2>=Assumptions!$B$14,"High",IF(V2>=Assumptions!$B$15,"Medium","Low")) -> Low | X2: =IF(H2=W2,"OK",IF(((H2="High")*3+(H2="Medium")*2+(H2="Low"))<((W2="High")*3+(W2="Medium")*2+(W2="Low")),"Under-rated","Over-rated")) -> OK | Y2: =INDEX(Assumptions!$L$22:$L$24,MATCH(H2,Assumptions!$K$22:$K$24,0)) -> 3 | Z2: =EDATE(G2,12*Y2) -> 47256 | AA2: =IF(Z2<Assumptions!$B$4,"Overdue",IF(Z2<=Assumptions!$B$4+60,"Due within 60 days","Current")) -> Current | AB2: =MAX(0,Assumptions!$B$4-Z2) -> 0 | AC2: =IF(COUNTIF($B$2:$B$41,B2)>1,"Duplicate","OK") -> OK | AD2: =IF(G2<F2,"Review before onboarding",IF(F2>Assumptions!$B$4,"Future onboarding","OK")) -> OK | AE2: =(P2>0)+(Q2>0)+(X2<>"OK")+(AC2<>"OK")+(AD2<>"OK")+(AA2="Overdue") -> 0
A3: C002 | B3: Nordic Precision Manufacturing GmbH | C3: Corporate | D3: Germany | E3: Manufacturing | F3: 44539 | G3: 45767 | H3: Low | I3: Y | J3: Y | K3: Y | L3: Y | M3: Clear | N3: N | O3: 0 | P3: =4-COUNTIF(I3:L3,"Y") -> 0 | Q3: =COUNTBLANK(A3:O3) -> 0 | R3: =IF(P3>0,"Incomplete - Docs",IF(M3<>"Clear","Incomplete - Screening","Complete")) -> Complete | S3: =IFERROR(INDEX(Assumptions!$B$22:$B$39,MATCH(D3,Assumptions!$A$22:$A$39,0)),0) -> 0 | T3: =IFERROR(INDEX(Assumptions!$F$22:$F$35,MATCH(E3,Assumptions!$E$22:$E$35,0)),0) -> 0 | U3: =IFERROR(INDEX(Assumptions!$I$22:$I$25,MATCH(C3,Assumptions!$H$22:$H$25,0)),0) -> 0 | V3: =S3+T3+U3+IF(N3="Y",Assumptions!$B$16,0) -> 0 | W3: =IF(V3>=Assumptions!$B$14,"High",IF(V3>=Assumptions!$B$15,"Medium","Low")) -> Low | X3: =IF(H3=W3,"OK",IF(((H3="High")*3+(H3="Medium")*2+(H3="Low"))<((W3="High")*3+(W3="Medium")*2+(W3="Low")),"Under-rated","Over-rated")) -> OK | Y3: =INDEX(Assumptions!$L$22:$L$24,MATCH(H3,Assumptions!$K$22:$K$24,0)) -> 3 | Z3: =EDATE(G3,12*Y3) -> 46863 | AA3: =IF(Z3<Assumptions!$B$4,"Overdue",IF(Z3<=Assumptions!$B$4+60,"Due within 60 days","Current")) -> Current | AB3: =MAX(0,Assumptions!$B$4-Z3) -> 0 | AC3: =IF(COUNTIF($B$2:$B$41,B3)>1,"Duplicate","OK") -> OK | AD3: =IF(G3<F3,"Review before onboarding",IF(F3>Assumptions!$B$4,"Future onboarding","OK")) -> OK | AE3: =(P3>0)+(Q3>0)+(X3<>"OK")+(AC3<>"OK")+(AD3<>"OK")+(AA3="Overdue") -> 0
A4: C003 | B4: Lotus Healthcare Systems Ltd | C4: Corporate | D4: India | E4: Healthcare | F4: 45229 | G4: 45619 | H4: Low | I4: Y | J4: Y | K4: Y | L4: Y | M4: Clear | N4: N | O4: 0 | P4: =4-COUNTIF(I4:L4,"Y") -> 0 | Q4: =COUNTBLANK(A4:O4) -> 0 | R4: =IF(P4>0,"Incomplete - Docs",IF(M4<>"Clear","Incomplete - Screening","Complete")) -> Complete | S4: =IFERROR(INDEX(Assumptions!$B$22:$B$39,MATCH(D4,Assumptions!$A$22:$A$39,0)),0) -> 0 | T4: =IFERROR(INDEX(Assumptions!$F$22:$F$35,MATCH(E4,Assumptions!$E$22:$E$35,0)),0) -> 0 | U4: =IFERROR(INDEX(Assumptions!$I$22:$I$25,MATCH(C4,Assumptions!$H$22:$H$25,0)),0) -> 0 | V4: =S4+T4+U4+IF(N4="Y",Assumptions!$B$16,0) -> 0 | W4: =IF(V4>=Assumptions!$B$14,"High",IF(V4>=Assumptions!$B$15,"Medium","Low")) -> Low | X4: =IF(H4=W4,"OK",IF(((H4="High")*3+(H4="Medium")*2+(H4="Low"))<((W4="High")*3+(W4="Medium")*2+(W4="Low")),"Under-rated","Over-rated")) -> OK | Y4: =INDEX(Assumptions!$L$22:$L$24,MATCH(H4,Assumptions!$K$22:$K$24,0)) -> 3 | Z4: =EDATE(G4,12*Y4) -> 46714 | AA4: =IF(Z4<Assumptions!$B$4,"Overdue",IF(Z4<=Assumptions!$B$4+60,"Due within 60 days","Current")) -> Current | AB4: =MAX(0,Assumptions!$B$4-Z4) -> 0 | AC4: =IF(COUNTIF($B$2:$B$41,B4)>1,"Duplicate","OK") -> OK | AD4: =IF(G4<F4,"Review before onboarding",IF(F4>Assumptions!$B$4,"Future onboarding","OK")) -> OK | AE4: =(P4>0)+(Q4>0)+(X4<>"OK")+(AC4<>"OK")+(AD4<>"OK")+(AA4="Overdue") -> 0
A5: C004 | B5: Thames Consulting Partners LLP | C5: Partnership | D5: United Kingdom | E5: Consulting | F5: 44739 | G5: 45376 | H5: Low | I5: Y | J5: Y | K5: Y | L5: Y | M5: Clear | N5: N | O5: 0 | P5: =4-COUNTIF(I5:L5,"Y") -> 0 | Q5: =COUNTBLANK(A5:O5) -> 0 | R5: =IF(P5>0,"Incomplete - Docs",IF(M5<>"Clear","Incomplete - Screening","Complete")) -> Complete | S5: =IFERROR(INDEX(Assumptions!$B$22:$B$39,MATCH(D5,Assumptions!$A$22:$A$39,0)),0) -> 0 | T5: =IFERROR(INDEX(Assumptions!$F$22:$F$35,MATCH(E5,Assumptions!$E$22:$E$35,0)),0) -> 1 | U5: =IFERROR(INDEX(Assumptions!$I$22:$I$25,MATCH(C5,Assumptions!$H$22:$H$25,0)),0) -> 1 | V5: =S5+T5+U5+IF(N5="Y",Assumptions!$B$16,0) -> 2 | W5: =IF(V5>=Assumptions!$B$14,"High",IF(V5>=Assumptions!$B$15,"Medium","Low")) -> Low | X5: =IF(H5=W5,"OK",IF(((H5="High")*3+(H5="Medium")*2+(H5="Low"))<((W5="High")*3+(W5="Medium")*2+(W5="Low")),"Under-rated","Over-rated")) -> OK | Y5: =INDEX(Assumptions!$L$22:$L$24,MATCH(H5,Assumptions!$K$22:$K$24,0)) -> 3 | Z5: =EDATE(G5,12*Y5) -> 46471 | AA5: =IF(Z5<Assumptions!$B$4,"Overdue",IF(Z5<=Assumptions!$B$4+60,"Due within 60 days","Current")) -> Current | AB5: =MAX(0,Assumptions!$B$4-Z5) -> 0 | AC5: =IF(COUNTIF($B$2:$B$41,B5)>1,"Duplicate","OK") -> OK | AD5: =IF(G5<F5,"Review before onboarding",IF(F5>Assumptions!$B$4,"Future onboarding","OK")) -> OK | AE5: =(P5>0)+(Q5>0)+(X5<>"OK")+(AC5<>"OK")+(AD5<>"OK")+(AA5="Overdue") -> 0
A6: C005 | B6: Spice Route Restaurants Group Inc | C6: Corporate | D6: United States | E6: Restaurants & Hospitality | F6: 43955 | G6: 45365 | H6: Low | I6: Y | J6: Y | K6: Y | L6: Y | M6: Clear | N6: N | O6: 40000 | P6: =4-COUNTIF(I6:L6,"Y") -> 0 | Q6: =COUNTBLANK(A6:O6) -> 0 | R6: =IF(P6>0,"Incomplete - Docs",IF(M6<>"Clear","Incomplete - Screening","Complete")) -> Complete | S6: =IFERROR(INDEX(Assumptions!$B$22:$B$39,MATCH(D6,Assumptions!$A$22:$A$39,0)),0) -> 0 | T6: =IFERROR(INDEX(Assumptions!$F$22:$F$35,MATCH(E6,Assumptions!$E$22:$E$35,0)),0) -> 2 | U6: =IFERROR(INDEX(Assumptions!$I$22:$I$25,MATCH(C6,Assumptions!$H$22:$H$25,0)),0) -> 0 | V6: =S6+T6+U6+IF(N6="Y",Assumptions!$B$16,0) -> 2 | W6: =IF(V6>=Assumptions!$B$14,"High",IF(V6>=Assumptions!$B$15,"Medium","Low")) -> Low | X6: =IF(H6=W6,"OK",IF(((H6="High")*3+(H6="Medium")*2+(H6="Low"))<((W6="High")*3+(W6="Medium")*2+(W6="Low")),"Under-rated","Over-rated")) -> OK | Y6: =INDEX(Assumptions!$L$22:$L$24,MATCH(H6,Assumptions!$K$22:$K$24,0)) -> 3 | Z6: =EDATE(G6,12*Y6) -> 46460 | AA6: =IF(Z6<Assumptions!$B$4,"Overdue",IF(Z6<=Assumptions!$B$4+60,"Due within 60 days","Current")) -> Current | AB6: =MAX(0,Assumptions!$B$4-Z6) -> 0 | AC6: =IF(COUNTIF($B$2:$B$41,B6)>1,"Duplicate","OK") -> OK | AD6: =IF(G6<F6,"Review before onboarding",IF(F6>Assumptions!$B$4,"Future onboarding","OK")) -> OK | AE6: =(P6>0)+(Q6>0)+(X6<>"OK")+(AC6<>"OK")+(AD6<>"OK")+(AA6="Overdue") -> 0
A7: C006 | B7: Meridian Textile Exports Pvt Ltd | C7: Corporate | D7: India | E7: Import/Export Trading | F7: 44326 | G7: 45645 | H7: Low | I7: Y | J7: Y | K7: Y | L7: Y | M7: Clear | N7: N | O7: 0 | P7: =4-COUNTIF(I7:L7,"Y") -> 0 | Q7: =COUNTBLANK(A7:O7) -> 0 | R7: =IF(P7>0,"Incomplete - Docs",IF(M7<>"Clear","Incomplete - Screening","Complete")) -> Complete | S7: =IFERROR(INDEX(Assumptions!$B$22:$B$39,MATCH(D7,Assumptions!$A$22:$A$39,0)),0) -> 0 | T7: =IFERROR(INDEX(Assumptions!$F$22:$F$35,MATCH(E7,Assumptions!$E$22:$E$35,0)),0) -> 2 | U7: =IFERROR(INDEX(Assumptions!$I$22:$I$25,MATCH(C7,Assumptions!$H$22:$H$25,0)),0) -> 0 | V7: =S7+T7+U7+IF(N7="Y",Assumptions!$B$16,0) -> 2 | W7: =IF(V7>=Assumptions!$B$14,"High",IF(V7>=Assumptions!$B$15,"Medium","Low")) -> Low | X7: =IF(H7=W7,"OK",IF(((H7="High")*3+(H7="Medium")*2+(H7="Low"))<((W7="High")*3+(W7="Medium")*2+(W7="Low")),"Under-rated","Over-rated")) -> OK | Y7: =INDEX(Assumptions!$L$22:$L$24,MATCH(H7,Assumptions!$K$22:$K$24,0)) -> 3 | Z7: =EDATE(G7,12*Y7) -> 46740 | AA7: =IF(Z7<Assumptions!$B$4,"Overdue",IF(Z7<=Assumptions!$B$4+60,"Due within 60 days","Current")) -> Current | AB7: =MAX(0,Assumptions!$B$4-Z7) -> 0 | AC7: =IF(COUNTIF($B$2:$B$41,B7)>1,"Duplicate","OK") -> Duplicate | AD7: =IF(G7<F7,"Review before onboarding",IF(F7>Assumptions!$B$4,"Future onboarding","OK")) -> OK | AE7: =(P7>0)+(Q7>0)+(X7<>"OK")+(AC7<>"OK")+(AD7<>"OK")+(AA7="Overdue") -> 1
A8: C007 | B8: Alpine Logistics AG | C8: Corporate | D8: Switzerland | E8: Logistics & Shipping | F8: 43483 | G8: 45267 | H8: Low | I8: Y | J8: Y | K8: Y | L8: Y | M8: Clear | N8: N | O8: 0 | P8: =4-COUNTIF(I8:L8,"Y") -> 0 | Q8: =COUNTBLANK(A8:O8) -> 0 | R8: =IF(P8>0,"Incomplete - Docs",IF(M8<>"Clear","Incomplete - Screening","Complete")) -> Complete | S8: =IFERROR(INDEX(Assumptions!$B$22:$B$39,MATCH(D8,Assumptions!$A$22:$A$39,0)),0) -> 0 | T8: =IFERROR(INDEX(Assumptions!$F$22:$F$35,MATCH(E8,Assumptions!$E$22:$E$35,0)),0) -> 1 | U8: =IFERROR(INDEX(Assumptions!$I$22:$I$25,MATCH(C8,Assumptions!$H$22:$H$25,0)),0) -> 0 | V8: =S8+T8+U8+IF(N8="Y",Assumptions!$B$16,0) -> 1 | W8: =IF(V8>=Assumptions!$B$14,"High",IF(V8>=Assumptions!$B$15,"Medium","Low")) -> Low | X8: =IF(H8=W8,"OK",IF(((H8="High")*3+(H8="Medium")*2+(H8="Low"))<((W8="High")*3+(W8="Medium")*2+(W8="Low")),"Under-rated","Over-rated")) -> OK | Y8: =INDEX(Assumptions!$L$22:$L$24,MATCH(H8,Assumptions!$K$22:$K$24,0)) -> 3 | Z8: =EDATE(G8,12*Y8) -> 46363 | AA8: =IF(Z8<Assumptions!$B$4,"Overdue",IF(Z8<=Assumptions!$B$4+60,"Due within 60 days","Current")) -> Due within 60 days | AB8: =MAX(0,Assumptions!$B$4-Z8) -> 0 | AC8: =IF(COUNTIF($B$2:$B$41,B8)>1,"Duplicate","OK") -> OK | AD8: =IF(G8<F8,"Review before onboarding",IF(F8>Assumptions!$B$4,"Future onboarding","OK")) -> OK | AE8: =(P8>0)+(Q8>0)+(X8<>"OK")+(AC8<>"OK")+(AD8<>"OK")+(AA8="Overdue") -> 0
A9: C008 | B9: Golden Crest Jewellers LLC | C9: Corporate | D9: United Arab Emirates | E9: Jewelry & Precious Metals | F9: 44394 | G9: 45695 | H9: Low | I9: Y | J9: Y | K9: Y | L9: Y | M9: Clear | N9: N | O9: 20000 | P9: =4-COUNTIF(I9:L9,"Y") -> 0 | Q9: =COUNTBLANK(A9:O9) -> 0 | R9: =IF(P9>0,"Incomplete - Docs",IF(M9<>"Clear","Incomplete - Screening","Complete")) -> Complete | S9: =IFERROR(INDEX(Assumptions!$B$22:$B$39,MATCH(D9,Assumptions!$A$22:$A$39,0)),0) -> 1 | T9: =IFERROR(INDEX(Assumptions!$F$22:$F$35,MATCH(E9,Assumptions!$E$22:$E$35,0)),0) -> 3 | U9: =IFERROR(INDEX(Assumptions!$I$22:$I$25,MATCH(C9,Assumptions!$H$22:$H$25,0)),0) -> 0 | V9: =S9+T9+U9+IF(N9="Y",Assumptions!$B$16,0) -> 4 | W9: =IF(V9>=Assumptions!$B$14,"High",IF(V9>=Assumptions!$B$15,"Medium","Low")) -> Medium | X9: =IF(H9=W9,"OK",IF(((H9="High")*3+(H9="Medium")*2+(H9="Low"))<((W9="High")*3+(W9="Medium")*2+(W9="Low")),"Under-rated","Over-rated")) -> Under-rated | Y9: =INDEX(Assumptions!$L$22:$L$24,MATCH(H9,Assumptions!$K$22:$K$24,0)) -> 3 | Z9: =EDATE(G9,12*Y9) -> 46790 | AA9: =IF(Z9<Assumptions!$B$4,"Overdue",IF(Z9<=Assumptions!$B$4+60,"Due within 60 days","Current")) -> Current | AB9: =MAX(0,Assumptions!$B$4-Z9) -> 0 | AC9: =IF(COUNTIF($B$2:$B$41,B9)>1,"Duplicate","OK") -> OK | AD9: =IF(G9<F9,"Review before onboarding",IF(F9>Assumptions!$B$4,"Future onboarding","OK")) -> OK | AE9: =(P9>0)+(Q9>0)+(X9<>"OK")+(AC9<>"OK")+(AD9<>"OK")+(AA9="Overdue") -> 1
A10: C009 | B10: Pinnacle Realty Developers Ltd | C10: Corporate | D10: Singapore | E10: Real Estate | F10: 44061 | G10: 45779 | H10: Medium | I10: Y | J10: Y | K10: Y | L10: Y | M10: Clear | N10: N | O10: 0 | P10: =4-COUNTIF(I10:L10,"Y") -> 0 | Q10: =COUNTBLANK(A10:O10) -> 0 | R10: =IF(P10>0,"Incomplete - Docs",IF(M10<>"Clear","Incomplete - Screening","Complete")) -> Complete | S10: =IFERROR(INDEX(Assumptions!$B$22:$B$39,MATCH(D10,Assumptions!$A$22:$A$39,0)),0) -> 0 | T10: =IFERROR(INDEX(Assumptions!$F$22:$F$35,MATCH(E10,Assumptions!$E$22:$E$35,0)),0) -> 2 | U10: =IFERROR(INDEX(Assumptions!$I$22:$I$25,MATCH(C10,Assumptions!$H$22:$H$25,0)),0) -> 0 | V10: =S10+T10+U10+IF(N10="Y",Assumptions!$B$16,0) -> 2 | W10: =IF(V10>=Assumptions!$B$14,"High",IF(V10>=Assumptions!$B$15,"Medium","Low")) -> Low | X10: =IF(H10=W10,"OK",IF(((H10="High")*3+(H10="Medium")*2+(H10="Low"))<((W10="High")*3+(W10="Medium")*2+(W10="Low")),"Under-rated","Over-rated")) -> Over-rated | Y10: =INDEX(Assumptions!$L$22:$L$24,MATCH(H10,Assumptions!$K$22:$K$24,0)) -> 2 | Z10: =EDATE(G10,12*Y10) -> 46509 | AA10: =IF(Z10<Assumptions!$B$4,"Overdue",IF(Z10<=Assumptions!$B$4+60,"Due within 60 days","Current")) -> Current | AB10: =MAX(0,Assumptions!$B$4-Z10) -> 0 | AC10: =IF(COUNTIF($B$2:$B$41,B10)>1,"Duplicate","OK") -> OK | AD10: =IF(G10<F10,"Review before onboarding",IF(F10>Assumptions!$B$4,"Future onboarding","OK")) -> OK | AE10: =(P10>0)+(Q10>0)+(X10<>"OK")+(AC10<>"OK")+(AD10<>"OK")+(AA10="Overdue") -> 1
A11: C010 | B11: Harbour Point Trading Co | C11: Corporate | D11: Hong Kong | E11: Import/Export Trading | F11: 45159 | G11: 45830 | H11: Medium | I11: Y | J11: Y | K11: Y | L11: Y | M11: Clear | N11: N | O11: 0 | P11: =4-COUNTIF(I11:L11,"Y") -> 0 | Q11: =COUNTBLANK(A11:O11) -> 0 | R11: =IF(P11>0,"Incomplete - Docs",IF(M11<>"Clear","Incomplete - Screening","Complete")) -> Complete | S11: =IFERROR(INDEX(Assumptions!$B$22:$B$39,MATCH(D11,Assumptions!$A$22:$A$39,0)),0) -> 1 | T11: =IFERROR(INDEX(Assumptions!$F$22:$F$35,MATCH(E11,Assumptions!$E$22:$E$35,0)),0) -> 2 | U11: =IFERROR(INDEX(Assumptions!$I$22:$I$25,MATCH(C11,Assumptions!$H$22:$H$25,0)),0) -> 0 | V11: =S11+T11+U11+IF(N11="Y",Assumptions!$B$16,0) -> 3 | W11: =IF(V11>=Assumptions!$B$14,"High",IF(V11>=Assumptions!$B$15,"Medium","Low")) -> Medium | X11: =IF(H11=W11,"OK",IF(((H11="High")*3+(H11="Medium")*2+(H11="Low"))<((W11="High")*3+(W11="Medium")*2+(W11="Low")),"Under-rated","Over-rated")) -> OK | Y11: =INDEX(Assumptions!$L$22:$L$24,MATCH(H11,Assumptions!$K$22:$K$24,0)) -> 2 | Z11: =EDATE(G11,12*Y11) -> 46560 | AA11: =IF(Z11<Assumptions!$B$4,"Overdue",IF(Z11<=Assumptions!$B$4+60,"Due within 60 days","Current")) -> Current | AB11: =MAX(0,Assumptions!$B$4-Z11) -> 0 | AC11: =IF(COUNTIF($B$2:$B$41,B11)>1,"Duplicate","OK") -> OK | AD11: =IF(G11<F11,"Review before onboarding",IF(F11>Assumptions!$B$4,"Future onboarding","OK")) -> OK | AE11: =(P11>0)+(Q11>0)+(X11<>"OK")+(AC11<>"OK")+(AD11<>"OK")+(AA11="Overdue") -> 0
A12: C011 | B12: Coral Reef Gaming Ltd | C12: Corporate | D12: Cayman Islands | E12: Casinos & Gaming | F12: 44124 | G12: 45561 | H12: Medium | I12: Y | J12: Y | K12: Y | L12: Y | M12: Clear | N12: N | O12: 0 | P12: =4-COUNTIF(I12:L12,"Y") -> 0 | Q12: =COUNTBLANK(A12:O12) -> 0 | R12: =IF(P12>0,"Incomplete - Docs",IF(M12<>"Clear","Incomplete - Screening","Complete")) -> Complete | S12: =IFERROR(INDEX(Assumptions!$B$22:$B$39,MATCH(D12,Assumptions!$A$22:$A$39,0)),0) -> 2 | T12: =IFERROR(INDEX(Assumptions!$F$22:$F$35,MATCH(E12,Assumptions!$E$22:$E$35,0)),0) -> 3 | U12: =IFERROR(INDEX(Assumptions!$I$22:$I$25,MATCH(C12,Assumptions!$H$22:$H$25,0)),0) -> 0 | V12: =S12+T12+U12+IF(N12="Y",Assumptions!$B$16,0) -> 5 | W12: =IF(V12>=Assumptions!$B$14,"High",IF(V12>=Assumptions!$B$15,"Medium","Low")) -> Medium | X12: =IF(H12=W12,"OK",IF(((H12="High")*3+(H12="Medium")*2+(H12="Low"))<((W12="High")*3+(W12="Medium")*2+(W12="Low")),"Under-rated","Over-rated")) -> OK | Y12: =INDEX(Assumptions!$L$22:$L$24,MATCH(H12,Assumptions!$K$22:$K$24,0)) -> 2 | Z12: =EDATE(G12,12*Y12) -> 46291 | AA12: =IF(Z12<Assumptions!$B$4,"Overdue",IF(Z12<=Assumptions!$B$4+60,"Due within 60 days","Current")) -> Overdue | AB12: =MAX(0,Assumptions!$B$4-Z12) -> 30 | AC12: =IF(COUNTIF($B$2:$B$41,B12)>1,"Duplicate","OK") -> OK | AD12: =IF(G12<F12,"Review before onboarding",IF(F12>Assumptions!$B$4,"Future onboarding","OK")) -> OK | AE12: =(P12>0)+(Q12>0)+(X12<>"OK")+(AC12<>"OK")+(AD12<>"OK")+(AA12="Overdue") -> 1
A13: C012 | B13: Brightline Retail Holdings Inc | C13: Corporate | D13: United States | E13: Retail | F13: 45793 | G13: 46199 | H13: Low | I13: Y | J13: Y | K13: Y | L13: Y | M13: Clear | N13: N | O13: 45000 | P13: =4-COUNTIF(I13:L13,"Y") -> 0 | Q13: =COUNTBLANK(A13:O13) -> 0 | R13: =IF(P13>0,"Incomplete - Docs",IF(M13<>"Clear","Incomplete - Screening","Complete")) -> Complete | S13: =IFERROR(INDEX(Assumptions!$B$22:$B$39,MATCH(D13,Assumptions!$A$22:$A$39,0)),0) -> 0 | T13: =IFERROR(INDEX(Assumptions!$F$22:$F$35,MATCH(E13,Assumptions!$E$22:$E$35,0)),0) -> 1 | U13: =IFERROR(INDEX(Assumptions!$I$22:$I$25,MATCH(C13,Assumptions!$H$22:$H$25,0)),0) -> 0 | V13: =S13+T13+U13+IF(N13="Y",Assumptions!$B$16,0) -> 1 | W13: =IF(V13>=Assumptions!$B$14,"High",IF(V13>=Assumptions!$B$15,"Medium","Low")) -> Low | X13: =IF(H13=W13,"OK",IF(((H13="High")*3+(H13="Medium")*2+(H13="Low"))<((W13="High")*3+(W13="Medium")*2+(W13="Low")),"Under-rated","Over-rated")) -> OK | Y13: =INDEX(Assumptions!$L$22:$L$24,MATCH(H13,Assumptions!$K$22:$K$24,0)) -> 3 | Z13: =EDATE(G13,12*Y13) -> 47295 | AA13: =IF(Z13<Assumptions!$B$4,"Overdue",IF(Z13<=Assumptions!$B$4+60,"Due within 60 days","Current")) -> Current | AB13: =MAX(0,Assumptions!$B$4-Z13) -> 0 | AC13: =IF(COUNTIF($B$2:$B$41,B13)>1,"Duplicate","OK") -> OK | AD13: =IF(G13<F13,"Review before onboarding",IF(F13>Assumptions!$B$4,"Future onboarding","OK")) -> OK | AE13: =(P13>0)+(Q13>0)+(X13<>"OK")+(AC13<>"OK")+(AD13<>"OK")+(AA13="Overdue") -> 0
... A24: C023 | B24: Cedar Hill Property Holdings Ltd | C24: Corporate | D24: United Kingdom | E24: Real Estate | F24: 44899 | G24: 45262 | H24: Low | I24: Y | J24: Y | K24: Y | L24: Y | M24: Clear | N24: N | O24: 0 | P24: =4-COUNTIF(I24:L24,"Y") -> 0 | Q24: =COUNTBLANK(A24:O24) -> 0 | R24: =IF(P24>0,"Incomplete - Docs",IF(M24<>"Clear","Incomplete - Screening","Complete")) -> Complete | S24: =IFERROR(INDEX(Assumptions!$B$22:$B$39,MATCH(D24,Assumptions!$A$22:$A$39,0)),0) -> 0 | T24: =IFERROR(INDEX(Assumptions!$F$22:$F$35,MATCH(E24,Assumptions!$E$22:$E$35,0)),0) -> 2 | U24: =IFERROR(INDEX(Assumptions!$I$22:$I$25,MATCH(C24,Assumptions!$H$22:$H$25,0)),0) -> 0 | V24: =S24+T24+U24+IF(N24="Y",Assumptions!$B$16,0) -> 2 | W24: =IF(V24>=Assumptions!$B$14,"High",IF(V24>=Assumptions!$B$15,"Medium","Low")) -> Low | X24: =IF(H24=W24,"OK",IF(((H24="High")*3+(H24="Medium")*2+(H24="Low"))<((W24="High")*3+(W24="Medium")*2+(W24="Low")),"Under-rated","Over-rated")) -> OK | Y24: =INDEX(Assumptions!$L$22:$L$24,MATCH(H24,Assumptions!$K$22:$K$24,0)) -> 3 | Z24: =EDATE(G24,12*Y24) -> 46358 | AA24: =IF(Z24<Assumptions!$B$4,"Overdue",IF(Z24<=Assumptions!$B$4+60,"Due within 60 days","Current")) -> Due within 60 days | AB24: =MAX(0,Assumptions!$B$4-Z24) -> 0 | AC24: =IF(COUNTIF($B$2:$B$41,B24)>1,"Duplicate","OK") -> OK | AD24: =IF(G24<F24,"Review before onboarding",IF(F24>Assumptions!$B$4,"Future onboarding","OK")) -> OK | AE24: =(P24>0)+(Q24>0)+(X24<>"OK")+(AC24<>"OK")+(AD24<>"OK")+(AA24="Overdue") -> 0
A25: C024 | B25: Sunrise Auto Traders LLC | C25: Corporate | D25: United States | F25: 44430 | G25: 45711 | H25: Low | I25: Y | J25: Y | K25: Y | L25: N | M25: Clear | N25: N | O25: 30000 | P25: =4-COUNTIF(I25:L25,"Y") -> 1 | Q25: =COUNTBLANK(A25:O25) -> 1 | R25: =IF(P25>0,"Incomplete - Docs",IF(M25<>"Clear","Incomplete - Screening","Complete")) -> Incomplete - Docs | S25: =IFERROR(INDEX(Assumptions!$B$22:$B$39,MATCH(D25,Assumptions!$A$22:$A$39,0)),0) -> 0 | T25: =IFERROR(INDEX(Assumptions!$F$22:$F$35,MATCH(E25,Assumptions!$E$22:$E$35,0)),0) -> 0 | U25: =IFERROR(INDEX(Assumptions!$I$22:$I$25,MATCH(C25,Assumptions!$H$22:$H$25,0)),0) -> 0 | V25: =S25+T25+U25+IF(N25="Y",Assumptions!$B$16,0) -> 0 | W25: =IF(V25>=Assumptions!$B$14,"High",IF(V25>=Assumptions!$B$15,"Medium","Low")) -> Low | X25: =IF(H25=W25,"OK",IF(((H25="High")*3+(H25="Medium")*2+(H25="Low"))<((W25="High")*3+(W25="Medium")*2+(W25="Low")),"Under-rated","Over-rated")) -> OK | Y25: =INDEX(Assumptions!$L$22:$L$24,MATCH(H25,Assumptions!$K$22:$K$24,0)) -> 3 | Z25: =EDATE(G25,12*Y25) -> 46806 | AA25: =IF(Z25<Assumptions!$B$4,"Overdue",IF(Z25<=Assumptions!$B$4+60,"Due within 60 days","Current")) -> Current | AB25: =MAX(0,Assumptions!$B$4-Z25) -> 0 | AC25: =IF(COUNTIF($B$2:$B$41,B25)>1,"Duplicate","OK") -> OK | AD25: =IF(G25<F25,"Review before onboarding",IF(F25>Assumptions!$B$4,"Future onboarding","OK")) -> OK | AE25: =(P25>0)+(Q25>0)+(X25<>"OK")+(AC25<>"OK")+(AD25<>"OK")+(AA25="Overdue") -> 2
A26: C025 | B26: Crescent Remit Services LLP | C26: Partnership | D26: Nigeria | E26: Money Services Business | F26: 45438 | G26: 46207 | H26: High | I26: Y | J26: Y | K26: Y | L26: Y | M26: Clear | N26: N | O26: 0 | P26: =4-COUNTIF(I26:L26,"Y") -> 0 | Q26: =COUNTBLANK(A26:O26) -> 0 | R26: =IF(P26>0,"Incomplete - Docs",IF(M26<>"Clear","Incomplete - Screening","Complete")) -> Complete | S26: =IFERROR(INDEX(Assumptions!$B$22:$B$39,MATCH(D26,Assumptions!$A$22:$A$39,0)),0) -> 2 | T26: =IFERROR(INDEX(Assumptions!$F$22:$F$35,MATCH(E26,Assumptions!$E$22:$E$35,0)),0) -> 3 | U26: =IFERROR(INDEX(Assumptions!$I$22:$I$25,MATCH(C26,Assumptions!$H$22:$H$25,0)),0) -> 1 | V26: =S26+T26+U26+IF(N26="Y",Assumptions!$B$16,0) -> 6 | W26: =IF(V26>=Assumptions!$B$14,"High",IF(V26>=Assumptions!$B$15,"Medium","Low")) -> High | X26: =IF(H26=W26,"OK",IF(((H26="High")*3+(H26="Medium")*2+(H26="Low"))<((W26="High")*3+(W26="Medium")*2+(W26="Low")),"Under-rated","Over-rated")) -> OK | Y26: =INDEX(Assumptions!$L$22:$L$24,MATCH(H26,Assumptions!$K$22:$K$24,0)) -> 1 | Z26: =EDATE(G26,12*Y26) -> 46572 | AA26: =IF(Z26<Assumptions!$B$4,"Overdue",IF(Z26<=Assumptions!$B$4+60,"Due within 60 days","Current")) -> Current | AB26: =MAX(0,Assumptions!$B$4-Z26) -> 0 | AC26: =IF(COUNTIF($B$2:$B$41,B26)>1,"Duplicate","OK") -> OK | AD26: =IF(G26<F26,"Review before onboarding",IF(F26>Assumptions!$B$4,"Future onboarding","OK")) -> OK | AE26: =(P26>0)+(Q26>0)+(X26<>"OK")+(AC26<>"OK")+(AD26<>"OK")+(AA26="Overdue") -> 0
A27: C026 | B27: Palm Bay Casino Resorts | C27: Partnership | D27: Panama | E27: Casinos & Gaming | F27: 44976 | G27: 45444 | H27: Medium | I27: Y | J27: Y | K27: Y | L27: Y | M27: Clear | N27: N | O27: 0 | P27: =4-COUNTIF(I27:L27,"Y") -> 0 | Q27: =COUNTBLANK(A27:O27) -> 0 | R27: =IF(P27>0,"Incomplete - Docs",IF(M27<>"Clear","Incomplete - Screening","Complete")) -> Complete | S27: =IFERROR(INDEX(Assumptions!$B$22:$B$39,MATCH(D27,Assumptions!$A$22:$A$39,0)),0) -> 2 | T27: =IFERROR(INDEX(Assumptions!$F$22:$F$35,MATCH(E27,Assumptions!$E$22:$E$35,0)),0) -> 3 | U27: =IFERROR(INDEX(Assumptions!$I$22:$I$25,MATCH(C27,Assumptions!$H$22:$H$25,0)),0) -> 1 | V27: =S27+T27+U27+IF(N27="Y",Assumptions!$B$16,0) -> 6 | W27: =IF(V27>=Assumptions!$B$14,"High",IF(V27>=Assumptions!$B$15,"Medium","Low")) -> High | X27: =IF(H27=W27,"OK",IF(((H27="High")*3+(H27="Medium")*2+(H27="Low"))<((W27="High")*3+(W27="Medium")*2+(W27="Low")),"Under-rated","Over-rated")) -> Under-rated | Y27: =INDEX(Assumptions!$L$22:$L$24,MATCH(H27,Assumptions!$K$22:$K$24,0)) -> 2 | Z27: =EDATE(G27,12*Y27) -> 46174 | AA27: =IF(Z27<Assumptions!$B$4,"Overdue",IF(Z27<=Assumptions!$B$4+60,"Due within 60 days","Current")) -> Overdue | AB27: =MAX(0,Assumptions!$B$4-Z27) -> 147 | AC27: =IF(COUNTIF($B$2:$B$41,B27)>1,"Duplicate","OK") -> OK | AD27: =IF(G27<F27,"Review before onboarding",IF(F27>Assumptions!$B$4,"Future onboarding","OK")) -> OK | AE27: =(P27>0)+(Q27>0)+(X27<>"OK")+(AC27<>"OK")+(AD27<>"OK")+(AA27="Overdue") -> 2
A28: C027 | B28: Irrawaddy Trade Links Ltd | C28: Corporate | D28: Hong Kong | E28: Import/Export Trading | F28: 43884 | G28: 45384 | H28: Low | I28: Y | J28: Y | K28: Y | L28: Y | M28: Clear | N28: N | O28: 0 | P28: =4-COUNTIF(I28:L28,"Y") -> 0 | Q28: =COUNTBLANK(A28:O28) -> 0 | R28: =IF(P28>0,"Incomplete - Docs",IF(M28<>"Clear","Incomplete - Screening","Complete")) -> Complete | S28: =IFERROR(INDEX(Assumptions!$B$22:$B$39,MATCH(D28,Assumptions!$A$22:$A$39,0)),0) -> 1 | T28: =IFERROR(INDEX(Assumptions!$F$22:$F$35,MATCH(E28,Assumptions!$E$22:$E$35,0)),0) -> 2 | U28: =IFERROR(INDEX(Assumptions!$I$22:$I$25,MATCH(C28,Assumptions!$H$22:$H$25,0)),0) -> 0 | V28: =S28+T28+U28+IF(N28="Y",Assumptions!$B$16,0) -> 3 | W28: =IF(V28>=Assumptions!$B$14,"High",IF(V28>=Assumptions!$B$15,"Medium","Low")) -> Medium | X28: =IF(H28=W28,"OK",IF(((H28="High")*3+(H28="Medium")*2+(H28="Low"))<((W28="High")*3+(W28="Medium")*2+(W28="Low")),"Under-rated","Over-rated")) -> Under-rated | Y28: =INDEX(Assumptions!$L$22:$L$24,MATCH(H28,Assumptions!$K$22:$K$24,0)) -> 3 | Z28: =EDATE(G28,12*Y28) -> 46479 | AA28: =IF(Z28<Assumptions!$B$4,"Overdue",IF(Z28<=Assumptions!$B$4+60,"Due within 60 days","Current")) -> Current | AB28: =MAX(0,Assumptions!$B$4-Z28) -> 0 | AC28: =IF(COUNTIF($B$2:$B$41,B28)>1,"Duplicate","OK") -> OK | AD28: =IF(G28<F28,"Review before onboarding",IF(F28>Assumptions!$B$4,"Future onboarding","OK")) -> OK | AE28: =(P28>0)+(Q28>0)+(X28<>"OK")+(AC28<>"OK")+(AD28<>"OK")+(AA28="Overdue") -> 1
A29: C028 | B29: Zurich Wealth Advisory AG | C29: Corporate | D29: Switzerland | E29: Consulting | F29: 43914 | G29: 45561 | H29: Low | I29: Y | J29: Y | K29: Y | L29: Y | M29: Clear | N29: N | O29: 0 | P29: =4-COUNTIF(I29:L29,"Y") -> 0 | Q29: =COUNTBLANK(A29:O29) -> 0 | R29: =IF(P29>0,"Incomplete - Docs",IF(M29<>"Clear","Incomplete - Screening","Complete")) -> Complete | S29: =IFERROR(INDEX(Assumptions!$B$22:$B$39,MATCH(D29,Assumptions!$A$22:$A$39,0)),0) -> 0 | T29: =IFERROR(INDEX(Assumptions!$F$22:$F$35,MATCH(E29,Assumptions!$E$22:$E$35,0)),0) -> 1 | U29: =IFERROR(INDEX(Assumptions!$I$22:$I$25,MATCH(C29,Assumptions!$H$22:$H$25,0)),0) -> 0 | V29: =S29+T29+U29+IF(N29="Y",Assumptions!$B$16,0) -> 1 | W29: =IF(V29>=Assumptions!$B$14,"High",IF(V29>=Assumptions!$B$15,"Medium","Low")) -> Low | X29: =IF(H29=W29,"OK",IF(((H29="High")*3+(H29="Medium")*2+(H29="Low"))<((W29="High")*3+(W29="Medium")*2+(W29="Low")),"Under-rated","Over-rated")) -> OK | Y29: =INDEX(Assumptions!$L$22:$L$24,MATCH(H29,Assumptions!$K$22:$K$24,0)) -> 3 | Z29: =EDATE(G29,12*Y29) -> 46656 | AA29: =IF(Z29<Assumptions!$B$4,"Overdue",IF(Z29<=Assumptions!$B$4+60,"Due within 60 days","Current")) -> Current | AB29: =MAX(0,Assumptions!$B$4-Z29) -> 0 | AC29: =IF(COUNTIF($B$2:$B$41,B29)>1,"Duplicate","OK") -> OK | AD29: =IF(G29<F29,"Review before onboarding",IF(F29>Assumptions!$B$4,"Future onboarding","OK")) -> OK | AE29: =(P29>0)+(Q29>0)+(X29<>"OK")+(AC29<>"OK")+(AD29<>"OK")+(AA29="Overdue") -> 0
A30: C029 | B30: The Halvorsen Family Trust | C30: Trust | D30: Switzerland | E30: Real Estate | F30: 45322 | G30: 46134 | H30: High | I30: Y | J30: Y | K30: Y | L30: Y | M30: Clear | N30: Y | O30: 0 | P30: =4-COUNTIF(I30:L30,"Y") -> 0 | Q30: =COUNTBLANK(A30:O30) -> 0 | R30: =IF(P30>0,"Incomplete - Docs",IF(M30<>"Clear","Incomplete - Screening","Complete")) -> Complete | S30: =IFERROR(INDEX(Assumptions!$B$22:$B$39,MATCH(D30,Assumptions!$A$22:$A$39,0)),0) -> 0 | T30: =IFERROR(INDEX(Assumptions!$F$22:$F$35,MATCH(E30,Assumptions!$E$22:$E$35,0)),0) -> 2 | U30: =IFERROR(INDEX(Assumptions!$I$22:$I$25,MATCH(C30,Assumptions!$H$22:$H$25,0)),0) -> 1 | V30: =S30+T30+U30+IF(N30="Y",Assumptions!$B$16,0) -> 6 | W30: =IF(V30>=Assumptions!$B$14,"High",IF(V30>=Assumptions!$B$15,"Medium","Low")) -> High | X30: =IF(H30=W30,"OK",IF(((H30="High")*3+(H30="Medium")*2+(H30="Low"))<((W30="High")*3+(W30="Medium")*2+(W30="Low")),"Under-rated","Over-rated")) -> OK | Y30: =INDEX(Assumptions!$L$22:$L$24,MATCH(H30,Assumptions!$K$22:$K$24,0)) -> 1 | Z30: =EDATE(G30,12*Y30) -> 46499 | AA30: =IF(Z30<Assumptions!$B$4,"Overdue",IF(Z30<=Assumptions!$B$4+60,"Due within 60 days","Current")) -> Current | AB30: =MAX(0,Assumptions!$B$4-Z30) -> 0 | AC30: =IF(COUNTIF($B$2:$B$41,B30)>1,"Duplicate","OK") -> OK | AD30: =IF(G30<F30,"Review before onboarding",IF(F30>Assumptions!$B$4,"Future onboarding","OK")) -> OK | AE30: =(P30>0)+(Q30>0)+(X30<>"OK")+(AC30<>"OK")+(AD30<>"OK")+(AA30="Overdue") -> 0
A31: C030 | B31: Delta Cloud Systems Pvt Ltd | C31: Corporate | D31: India | E31: Software/IT | F31: 44621 | G31: 46256 | H31: Low | I31: Y | J31: Y | K31: Y | L31: Y | M31: Clear | N31: N | O31: 0 | P31: =4-COUNTIF(I31:L31,"Y") -> 0 | Q31: =COUNTBLANK(A31:O31) -> 0 | R31: =IF(P31>0,"Incomplete - Docs",IF(M31<>"Clear","Incomplete - Screening","Complete")) -> Complete | S31: =IFERROR(INDEX(Assumptions!$B$22:$B$39,MATCH(D31,Assumptions!$A$22:$A$39,0)),0) -> 0 | T31: =IFERROR(INDEX(Assumptions!$F$22:$F$35,MATCH(E31,Assumptions!$E$22:$E$35,0)),0) -> 0 | U31: =IFERROR(INDEX(Assumptions!$I$22:$I$25,MATCH(C31,Assumptions!$H$22:$H$25,0)),0) -> 0 | V31: =S31+T31+U31+IF(N31="Y",Assumptions!$B$16,0) -> 0 | W31: =IF(V31>=Assumptions!$B$14,"High",IF(V31>=Assumptions!$B$15,"Medium","Low")) -> Low | X31: =IF(H31=W31,"OK",IF(((H31="High")*3+(H31="Medium")*2+(H31="Low"))<((W31="High")*3+(W31="Medium")*2+(W31="Low")),"Under-rated","Over-rated")) -> OK | Y31: =INDEX(Assumptions!$L$22:$L$24,MATCH(H31,Assumptions!$K$22:$K$24,0)) -> 3 | Z31: =EDATE(G31,12*Y31) -> 47352 | AA31: =IF(Z31<Assumptions!$B$4,"Overdue",IF(Z31<=Assumptions!$B$4+60,"Due within 60 days","Current")) -> Current | AB31: =MAX(0,Assumptions!$B$4-Z31) -> 0 | AC31: =IF(COUNTIF($B$2:$B$41,B31)>1,"Duplicate","OK") -> OK | AD31: =IF(G31<F31,"Review before onboarding",IF(F31>Assumptions!$B$4,"Future onboarding","OK")) -> OK | AE31: =(P31>0)+(Q31>0)+(X31<>"OK")+(AC31<>"OK")+(AD31<>"OK")+(AA31="Overdue") -> 0
A32: C031 | B32: Meridian Textile Exports Pvt Ltd | C32: Corporate | D32: India | E32: Import/Export Trading | F32: 44980 | G32: 45904 | H32: Low | I32: Y | J32: Y | K32: Y | L32: Y | M32: Clear | N32: N | O32: 0 | P32: =4-COUNTIF(I32:L32,"Y") -> 0 | Q32: =COUNTBLANK(A32:O32) -> 0 | R32: =IF(P32>0,"Incomplete - Docs",IF(M32<>"Clear","Incomplete - Screening","Complete")) -> Complete | S32: =IFERROR(INDEX(Assumptions!$B$22:$B$39,MATCH(D32,Assumptions!$A$22:$A$39,0)),0) -> 0 | T32: =IFERROR(INDEX(Assumptions!$F$22:$F$35,MATCH(E32,Assumptions!$E$22:$E$35,0)),0) -> 2 | U32: =IFERROR(INDEX(Assumptions!$I$22:$I$25,MATCH(C32,Assumptions!$H$22:$H$25,0)),0) -> 0 | V32: =S32+T32+U32+IF(N32="Y",Assumptions!$B$16,0) -> 2 | W32: =IF(V32>=Assumptions!$B$14,"High",IF(V32>=Assumptions!$B$15,"Medium","Low")) -> Low | X32: =IF(H32=W32,"OK",IF(((H32="High")*3+(H32="Medium")*2+(H32="Low"))<((W32="High")*3+(W32="Medium")*2+(W32="Low")),"Under-rated","Over-rated")) -> OK | Y32: =INDEX(Assumptions!$L$22:$L$24,MATCH(H32,Assumptions!$K$22:$K$24,0)) -> 3 | Z32: =EDATE(G32,12*Y32) -> 47000 | AA32: =IF(Z32<Assumptions!$B$4,"Overdue",IF(Z32<=Assumptions!$B$4+60,"Due within 60 days","Current")) -> Current | AB32: =MAX(0,Assumptions!$B$4-Z32) -> 0 | AC32: =IF(COUNTIF($B$2:$B$41,B32)>1,"Duplicate","OK") -> Duplicate | AD32: =IF(G32<F32,"Review before onboarding",IF(F32>Assumptions!$B$4,"Future onboarding","OK")) -> OK | AE32: =(P32>0)+(Q32>0)+(X32<>"OK")+(AC32<>"OK")+(AD32<>"OK")+(AA32="Overdue") -> 1
A33: C032 | B33: Anatolia Steel Works AS | C33: Corporate | D33: Turkey | E33: Manufacturing | F33: 44034 | G33: 45078 | H33: Low | I33: Y | J33: Y | K33: Y | L33: Y | M33: Clear | N33: N | O33: 0 | P33: =4-COUNTIF(I33:L33,"Y") -> 0 | Q33: =COUNTBLANK(A33:O33) -> 0 | R33: =IF(P33>0,"Incomplete - Docs",IF(M33<>"Clear","Incomplete - Screening","Complete")) -> Complete | S33: =IFERROR(INDEX(Assumptions!$B$22:$B$39,MATCH(D33,Assumptions!$A$22:$A$39,0)),0) -> 1 | T33: =IFERROR(INDEX(Assumptions!$F$22:$F$35,MATCH(E33,Assumptions!$E$22:$E$35,0)),0) -> 0 | U33: =IFERROR(INDEX(Assumptions!$I$22:$I$25,MATCH(C33,Assumptions!$H$22:$H$25,0)),0) -> 0 | V33: =S33+T33+U33+IF(N33="Y",Assumptions!$B$16,0) -> 1 | W33: =IF(V33>=Assumptions!$B$14,"High",IF(V33>=Assumptions!$B$15,"Medium","Low")) -> Low | X33: =IF(H33=W33,"OK",IF(((H33="High")*3+(H33="Medium")*2+(H33="Low"))<((W33="High")*3+(W33="Medium")*2+(W33="Low")),"Under-rated","Over-rated")) -> OK | Y33: =INDEX(Assumptions!$L$22:$L$24,MATCH(H33,Assumptions!$K$22:$K$24,0)) -> 3 | Z33: =EDATE(G33,12*Y33) -> 46174 | AA33: =IF(Z33<Assumptions!$B$4,"Overdue",IF(Z33<=Assumptions!$B$4+60,"Due within 60 days","Current")) -> Overdue | AB33: =MAX(0,Assumptions!$B$4-Z33) -> 147 | AC33: =IF(COUNTIF($B$2:$B$41,B33)>1,"Duplicate","OK") -> OK | AD33: =IF(G33<F33,"Review before onboarding",IF(F33>Assumptions!$B$4,"Future onboarding","OK")) -> OK | AE33: =(P33>0)+(Q33>0)+(X33<>"OK")+(AC33<>"OK")+(AD33<>"OK")+(AA33="Overdue") -> 1
A34: C033 | B34: Lakeview Medical Supplies Inc | C34: Corporate | D34: Canada | E34: Healthcare | F34: 45193 | G34: 46189 | H34: Low | I34: Y | J34: Y | K34: N | L34: Y | M34: Clear | N34: N | O34: 0 | P34: =4-COUNTIF(I34:L34,"Y") -> 1 | Q34: =COUNTBLANK(A34:O34) -> 0 | R34: =IF(P34>0,"Incomplete - Docs",IF(M34<>"Clear","Incomplete - Screening","Complete")) -> Incomplete - Docs | S34: =IFERROR(INDEX(Assumptions!$B$22:$B$39,MATCH(D34,Assumptions!$A$22:$A$39,0)),0) -> 0 | T34: =IFERROR(INDEX(Assumptions!$F$22:$F$35,MATCH(E34,Assumptions!$E$22:$E$35,0)),0) -> 0 | U34: =IFERROR(INDEX(Assumptions!$I$22:$I$25,MATCH(C34,Assumptions!$H$22:$H$25,0)),0) -> 0 | V34: =S34+T34+U34+IF(N34="Y",Assumptions!$B$16,0) -> 0 | W34: =IF(V34>=Assumptions!$B$14,"High",IF(V34>=Assumptions!$B$15,"Medium","Low")) -> Low | X34: =IF(H34=W34,"OK",IF(((H34="High")*3+(H34="Medium")*2+(H34="Low"))<((W34="High")*3+(W34="Medium")*2+(W34="Low")),"Under-rated","Over-rated")) -> OK | Y34: =INDEX(Assumptions!$L$22:$L$24,MATCH(H34,Assumptions!$K$22:$K$24,0)) -> 3 | Z34: =EDATE(G34,12*Y34) -> 47285 | AA34: =IF(Z34<Assumptions!$B$4,"Overdue",IF(Z34<=Assumptions!$B$4+60,"Due within 60 days","Current")) -> Current | AB34: =MAX(0,Assumptions!$B$4-Z34) -> 0 | AC34: =IF(COUNTIF($B$2:$B$41,B34)>1,"Duplicate","OK") -> OK | AD34: =IF(G34<F34,"Review before onboarding",IF(F34>Assumptions!$B$4,"Future onboarding","OK")) -> OK | AE34: =(P34>0)+(Q34>0)+(X34<>"OK")+(AC34<>"OK")+(AD34<>"OK")+(AA34="Overdue") -> 1
A35: C034 | B35: Skyline Hospitality Group Ltd | C35: Corporate | D35: India | E35: Restaurants & Hospitality | F35: 43990 | G35: 45369 | H35: Low | I35: Y | J35: Y | K35: Y | L35: Y | M35: Clear | N35: N | O35: 25000 | P35: =4-COUNTIF(I35:L35,"Y") -> 0 | Q35: =COUNTBLANK(A35:O35) -> 0 | R35: =IF(P35>0,"Incomplete - Docs",IF(M35<>"Clear","Incomplete - Screening","Complete")) -> Complete | S35: =IFERROR(INDEX(Assumptions!$B$22:$B$39,MATCH(D35,Assumptions!$A$22:$A$39,0)),0) -> 0 | T35: =IFERROR(INDEX(Assumptions!$F$22:$F$35,MATCH(E35,Assumptions!$E$22:$E$35,0)),0) -> 2 | U35: =IFERROR(INDEX(Assumptions!$I$22:$I$25,MATCH(C35,Assumptions!$H$22:$H$25,0)),0) -> 0 | V35: =S35+T35+U35+IF(N35="Y",Assumptions!$B$16,0) -> 2 | W35: =IF(V35>=Assumptions!$B$14,"High",IF(V35>=Assumptions!$B$15,"Medium","Low")) -> Low | X35: =IF(H35=W35,"OK",IF(((H35="High")*3+(H35="Medium")*2+(H35="Low"))<((W35="High")*3+(W35="Medium")*2+(W35="Low")),"Under-rated","Over-rated")) -> OK | Y35: =INDEX(Assumptions!$L$22:$L$24,MATCH(H35,Assumptions!$K$22:$K$24,0)) -> 3 | Z35: =EDATE(G35,12*Y35) -> 46464 | AA35: =IF(Z35<Assumptions!$B$4,"Overdue",IF(Z35<=Assumptions!$B$4+60,"Due within 60 days","Current")) -> Current | AB35: =MAX(0,Assumptions!$B$4-Z35) -> 0 | AC35: =IF(COUNTIF($B$2:$B$41,B35)>1,"Duplicate","OK") -> OK | AD35: =IF(G35<F35,"Review before onboarding",IF(F35>Assumptions!$B$4,"Future onboarding","OK")) -> OK | AE35: =(P35>0)+(Q35>0)+(X35<>"OK")+(AC35<>"OK")+(AD35<>"OK")+(AA35="Overdue") -> 0
A36: C035 | B36: Granite Peak Mining Services Ltd | C36: Corporate | D36: Canada | E36: Logistics & Shipping | F36: 43855 | G36: 45055 | H36: Low | I36: Y | J36: Y | K36: Y | L36: Y | M36: Clear | N36: N | O36: 0 | P36: =4-COUNTIF(I36:L36,"Y") -> 0 | Q36: =COUNTBLANK(A36:O36) -> 0 | R36: =IF(P36>0,"Incomplete - Docs",IF(M36<>"Clear","Incomplete - Screening","Complete")) -> Complete | S36: =IFERROR(INDEX(Assumptions!$B$22:$B$39,MATCH(D36,Assumptions!$A$22:$A$39,0)),0) -> 0 | T36: =IFERROR(INDEX(Assumptions!$F$22:$F$35,MATCH(E36,Assumptions!$E$22:$E$35,0)),0) -> 1 | U36: =IFERROR(INDEX(Assumptions!$I$22:$I$25,MATCH(C36,Assumptions!$H$22:$H$25,0)),0) -> 0 | V36: =S36+T36+U36+IF(N36="Y",Assumptions!$B$16,0) -> 1 | W36: =IF(V36>=Assumptions!$B$14,"High",IF(V36>=Assumptions!$B$15,"Medium","Low")) -> Low | X36: =IF(H36=W36,"OK",IF(((H36="High")*3+(H36="Medium")*2+(H36="Low"))<((W36="High")*3+(W36="Medium")*2+(W36="Low")),"Under-rated","Over-rated")) -> OK | Y36: =INDEX(Assumptions!$L$22:$L$24,MATCH(H36,Assumptions!$K$22:$K$24,0)) -> 3 | Z36: =EDATE(G36,12*Y36) -> 46151 | AA36: =IF(Z36<Assumptions!$B$4,"Overdue",IF(Z36<=Assumptions!$B$4+60,"Due within 60 days","Current")) -> Overdue | AB36: =MAX(0,Assumptions!$B$4-Z36) -> 170 | AC36: =IF(COUNTIF($B$2:$B$41,B36)>1,"Duplicate","OK") -> OK | AD36: =IF(G36<F36,"Review before onboarding",IF(F36>Assumptions!$B$4,"Future onboarding","OK")) -> OK | AE36: =(P36>0)+(Q36>0)+(X36<>"OK")+(AC36<>"OK")+(AD36<>"OK")+(AA36="Overdue") -> 1
A37: C036 | B37: Baltic Star Shipping Ltd | C37: Corporate | D37: Cyprus | E37: Logistics & Shipping | F37: 44975 | G37: 45393 | H37: Low | I37: Y | J37: Y | K37: Y | L37: Y | M37: Potential Match | N37: N | O37: 0 | P37: =4-COUNTIF(I37:L37,"Y") -> 0 | Q37: =COUNTBLANK(A37:O37) -> 0 | R37: =IF(P37>0,"Incomplete - Docs",IF(M37<>"Clear","Incomplete - Screening","Complete")) -> Incomplete - Screening | S37: =IFERROR(INDEX(Assumptions!$B$22:$B$39,MATCH(D37,Assumptions!$A$22:$A$39,0)),0) -> 1 | T37: =IFERROR(INDEX(Assumptions!$F$22:$F$35,MATCH(E37,Assumptions!$E$22:$E$35,0)),0) -> 1 | U37: =IFERROR(INDEX(Assumptions!$I$22:$I$25,MATCH(C37,Assumptions!$H$22:$H$25,0)),0) -> 0 | V37: =S37+T37+U37+IF(N37="Y",Assumptions!$B$16,0) -> 2 | W37: =IF(V37>=Assumptions!$B$14,"High",IF(V37>=Assumptions!$B$15,"Medium","Low")) -> Low | X37: =IF(H37=W37,"OK",IF(((H37="High")*3+(H37="Medium")*2+(H37="Low"))<((W37="High")*3+(W37="Medium")*2+(W37="Low")),"Under-rated","Over-rated")) -> OK | Y37: =INDEX(Assumptions!$L$22:$L$24,MATCH(H37,Assumptions!$K$22:$K$24,0)) -> 3 | Z37: =EDATE(G37,12*Y37) -> 46488 | AA37: =IF(Z37<Assumptions!$B$4,"Overdue",IF(Z37<=Assumptions!$B$4+60,"Due within 60 days","Current")) -> Current | AB37: =MAX(0,Assumptions!$B$4-Z37) -> 0 | AC37: =IF(COUNTIF($B$2:$B$41,B37)>1,"Duplicate","OK") -> OK | AD37: =IF(G37<F37,"Review before onboarding",IF(F37>Assumptions!$B$4,"Future onboarding","OK")) -> OK | AE37: =(P37>0)+(Q37>0)+(X37<>"OK")+(AC37<>"OK")+(AD37<>"OK")+(AA37="Overdue") -> 0
A38: C037 | B38: Emerald Isle Software Ltd | C38: Corporate | D38: United Kingdom | E38: Software/IT | F38: 44629 | G38: 45846 | H38: Low | I38: Y | J38: Y | K38: Y | L38: Y | M38: Clear | N38: N | O38: 0 | P38: =4-COUNTIF(I38:L38,"Y") -> 0 | Q38: =COUNTBLANK(A38:O38) -> 0 | R38: =IF(P38>0,"Incomplete - Docs",IF(M38<>"Clear","Incomplete - Screening","Complete")) -> Complete | S38: =IFERROR(INDEX(Assumptions!$B$22:$B$39,MATCH(D38,Assumptions!$A$22:$A$39,0)),0) -> 0 | T38: =IFERROR(INDEX(Assumptions!$F$22:$F$35,MATCH(E38,Assumptions!$E$22:$E$35,0)),0) -> 0 | U38: =IFERROR(INDEX(Assumptions!$I$22:$I$25,MATCH(C38,Assumptions!$H$22:$H$25,0)),0) -> 0 | V38: =S38+T38+U38+IF(N38="Y",Assumptions!$B$16,0) -> 0 | W38: =IF(V38>=Assumptions!$B$14,"High",IF(V38>=Assumptions!$B$15,"Medium","Low")) -> Low | X38: =IF(H38=W38,"OK",IF(((H38="High")*3+(H38="Medium")*2+(H38="Low"))<((W38="High")*3+(W38="Medium")*2+(W38="Low")),"Under-rated","Over-rated")) -> OK | Y38: =INDEX(Assumptions!$L$22:$L$24,MATCH(H38,Assumptions!$K$22:$K$24,0)) -> 3 | Z38: =EDATE(G38,12*Y38) -> 46942 | AA38: =IF(Z38<Assumptions!$B$4,"Overdue",IF(Z38<=Assumptions!$B$4+60,"Due within 60 days","Current")) -> Current | AB38: =MAX(0,Assumptions!$B$4-Z38) -> 0 | AC38: =IF(COUNTIF($B$2:$B$41,B38)>1,"Duplicate","OK") -> OK | AD38: =IF(G38<F38,"Review before onboarding",IF(F38>Assumptions!$B$4,"Future onboarding","OK")) -> OK | AE38: =(P38>0)+(Q38>0)+(X38<>"OK")+(AC38<>"OK")+(AD38<>"OK")+(AA38="Overdue") -> 0
A39: C038 | B39: Zenith Wellness Clinics Pvt Ltd | C39: Corporate | D39: India | E39: Healthcare | F39: 46296 | G39: 46296 | H39: Low | I39: N | J39: N | L39: N | M39: Not Done | N39: N | O39: 0 | P39: =4-COUNTIF(I39:L39,"Y") -> 4 | Q39: =COUNTBLANK(A39:O39) -> 1 | R39: =IF(P39>0,"Incomplete - Docs",IF(M39<>"Clear","Incomplete - Screening","Complete")) -> Incomplete - Docs | S39: =IFERROR(INDEX(Assumptions!$B$22:$B$39,MATCH(D39,Assumptions!$A$22:$A$39,0)),0) -> 0 | T39: =IFERROR(INDEX(Assumptions!$F$22:$F$35,MATCH(E39,Assumptions!$E$22:$E$35,0)),0) -> 0 | U39: =IFERROR(INDEX(Assumptions!$I$22:$I$25,MATCH(C39,Assumptions!$H$22:$H$25,0)),0) -> 0 | V39: =S39+T39+U39+IF(N39="Y",Assumptions!$B$16,0) -> 0 | W39: =IF(V39>=Assumptions!$B$14,"High",IF(V39>=Assumptions!$B$15,"Medium","Low")) -> Low | X39: =IF(H39=W39,"OK",IF(((H39="High")*3+(H39="Medium")*2+(H39="Low"))<((W39="High")*3+(W39="Medium")*2+(W39="Low")),"Under-rated","Over-rated")) -> OK | Y39: =INDEX(Assumptions!$L$22:$L$24,MATCH(H39,Assumptions!$K$22:$K$24,0)) -> 3 | Z39: =EDATE(G39,12*Y39) -> 47392 | AA39: =IF(Z39<Assumptions!$B$4,"Overdue",IF(Z39<=Assumptions!$B$4+60,"Due within 60 days","Current")) -> Current | AB39: =MAX(0,Assumptions!$B$4-Z39) -> 0 | AC39: =IF(COUNTIF($B$2:$B$41,B39)>1,"Duplicate","OK") -> OK | AD39: =IF(G39<F39,"Review before onboarding",IF(F39>Assumptions!$B$4,"Future onboarding","OK")) -> OK | AE39: =(P39>0)+(Q39>0)+(X39<>"OK")+(AC39<>"OK")+(AD39<>"OK")+(AA39="Overdue") -> 2
A40: C039 | B40: Ridgeway Used Cars Ltd | C40: Corporate | D40: United Kingdom | E40: Used Vehicle Dealers | F40: 43744 | G40: 45460 | H40: Low | I40: Y | J40: Y | K40: Y | L40: Y | M40: Clear | N40: N | O40: 35000 | P40: =4-COUNTIF(I40:L40,"Y") -> 0 | Q40: =COUNTBLANK(A40:O40) -> 0 | R40: =IF(P40>0,"Incomplete - Docs",IF(M40<>"Clear","Incomplete - Screening","Complete")) -> Complete | S40: =IFERROR(INDEX(Assumptions!$B$22:$B$39,MATCH(D40,Assumptions!$A$22:$A$39,0)),0) -> 0 | T40: =IFERROR(INDEX(Assumptions!$F$22:$F$35,MATCH(E40,Assumptions!$E$22:$E$35,0)),0) -> 2 | U40: =IFERROR(INDEX(Assumptions!$I$22:$I$25,MATCH(C40,Assumptions!$H$22:$H$25,0)),0) -> 0 | V40: =S40+T40+U40+IF(N40="Y",Assumptions!$B$16,0) -> 2 | W40: =IF(V40>=Assumptions!$B$14,"High",IF(V40>=Assumptions!$B$15,"Medium","Low")) -> Low | X40: =IF(H40=W40,"OK",IF(((H40="High")*3+(H40="Medium")*2+(H40="Low"))<((W40="High")*3+(W40="Medium")*2+(W40="Low")),"Under-rated","Over-rated")) -> OK | Y40: =INDEX(Assumptions!$L$22:$L$24,MATCH(H40,Assumptions!$K$22:$K$24,0)) -> 3 | Z40: =EDATE(G40,12*Y40) -> 46555 | AA40: =IF(Z40<Assumptions!$B$4,"Overdue",IF(Z40<=Assumptions!$B$4+60,"Due within 60 days","Current")) -> Current | AB40: =MAX(0,Assumptions!$B$4-Z40) -> 0 | AC40: =IF(COUNTIF($B$2:$B$41,B40)>1,"Duplicate","OK") -> OK | AD40: =IF(G40<F40,"Review before onboarding",IF(F40>Assumptions!$B$4,"Future onboarding","OK")) -> OK | AE40: =(P40>0)+(Q40>0)+(X40<>"OK")+(AC40<>"OK")+(AD40<>"OK")+(AA40="Overdue") -> 0
A41: C040 | B41: Orchid Textiles Pvt Ltd | C41: Corporate | D41: India | E41: Manufacturing | F41: 43985 | G41: 45394 | H41: Low | I41: Y | J41: Y | K41: Y | L41: Y | M41: Clear | N41: N | O41: 0 | P41: =4-COUNTIF(I41:L41,"Y") -> 0 | Q41: =COUNTBLANK(A41:O41) -> 0 | R41: =IF(P41>0,"Incomplete - Docs",IF(M41<>"Clear","Incomplete - Screening","Complete")) -> Complete | S41: =IFERROR(INDEX(Assumptions!$B$22:$B$39,MATCH(D41,Assumptions!$A$22:$A$39,0)),0) -> 0 | T41: =IFERROR(INDEX(Assumptions!$F$22:$F$35,MATCH(E41,Assumptions!$E$22:$E$35,0)),0) -> 0 | U41: =IFERROR(INDEX(Assumptions!$I$22:$I$25,MATCH(C41,Assumptions!$H$22:$H$25,0)),0) -> 0 | V41: =S41+T41+U41+IF(N41="Y",Assumptions!$B$16,0) -> 0 | W41: =IF(V41>=Assumptions!$B$14,"High",IF(V41>=Assumptions!$B$15,"Medium","Low")) -> Low | X41: =IF(H41=W41,"OK",IF(((H41="High")*3+(H41="Medium")*2+(H41="Low"))<((W41="High")*3+(W41="Medium")*2+(W41="Low")),"Under-rated","Over-rated")) -> OK | Y41: =INDEX(Assumptions!$L$22:$L$24,MATCH(H41,Assumptions!$K$22:$K$24,0)) -> 3 | Z41: =EDATE(G41,12*Y41) -> 46489 | AA41: =IF(Z41<Assumptions!$B$4,"Overdue",IF(Z41<=Assumptions!$B$4+60,"Due within 60 days","Current")) -> Current | AB41: =MAX(0,Assumptions!$B$4-Z41) -> 0 | AC41: =IF(COUNTIF($B$2:$B$41,B41)>1,"Duplicate","OK") -> OK | AD41: =IF(G41<F41,"Review before onboarding",IF(F41>Assumptions!$B$4,"Future onboarding","OK")) -> OK | AE41: =(P41>0)+(Q41>0)+(X41<>"OK")+(AC41<>"OK")+(AD41<>"OK")+(AA41="Overdue") -> 0

Sheet Transactions
A1: Txn ID | B1: Txn Date | C1: Client ID | D1: Txn Type | E1: Amount (USD) | F1: Counterparty Country | G1: Narrative | H1: Client Name | I1: Cash? (Y/N) | J1: Direction | K1: Near-Threshold Cash? | L1: Counterparty Country Score | M1: Daily Cash Total (client / day / direction) | N1: CTR Trigger | O1: Client KYC File Status
A2: T0001 | B2: 46266 | C2: C003 | D2: Wire In | E2: 17700 | F2: Canada | G2: Customer receipt | H2: =IFERROR(INDEX(Client_Master!$B$2:$B$41,MATCH(C2,Client_Master!$A$2:$A$41,0)),"UNKNOWN CLIENT") -> Lotus Healthcare Systems Ltd | I2: =IF(LEFT(D2,4)="Cash","Y","N") -> N | J2: =IF(OR(D2="Cash Deposit",D2="Wire In"),"In","Out") -> In | K2: =IF(AND(I2="Y",E2>=Assumptions!$B$6,E2<=Assumptions!$B$5),"Y","N") -> N | L2: =IFERROR(INDEX(Assumptions!$B$22:$B$39,MATCH(F2,Assumptions!$A$22:$A$39,0)),0) -> 0 | M2: =IF(I2="Y",SUMIFS($E$2:$E$114,$C$2:$C$114,C2,$B$2:$B$114,B2,$I$2:$I$114,"Y",$J$2:$J$114,J2),0) -> 0 | N2: =IF(M2>Assumptions!$B$5,"CTR","") | O2: =IFERROR(INDEX(Client_Master!$R$2:$R$41,MATCH(C2,Client_Master!$A$2:$A$41,0)),"No KYC record") -> Complete
A3: T0002 | B3: 46266 | C3: C023 | D3: Wire Out | E3: 78700 | F3: Germany | G3: Trade settlement | H3: =IFERROR(INDEX(Client_Master!$B$2:$B$41,MATCH(C3,Client_Master!$A$2:$A$41,0)),"UNKNOWN CLIENT") -> Cedar Hill Property Holdings Ltd | I3: =IF(LEFT(D3,4)="Cash","Y","N") -> N | J3: =IF(OR(D3="Cash Deposit",D3="Wire In"),"In","Out") -> Out | K3: =IF(AND(I3="Y",E3>=Assumptions!$B$6,E3<=Assumptions!$B$5),"Y","N") -> N | L3: =IFERROR(INDEX(Assumptions!$B$22:$B$39,MATCH(F3,Assumptions!$A$22:$A$39,0)),0) -> 0 | M3: =IF(I3="Y",SUMIFS($E$2:$E$114,$C$2:$C$114,C3,$B$2:$B$114,B3,$I$2:$I$114,"Y",$J$2:$J$114,J3),0) -> 0 | N3: =IF(M3>Assumptions!$B$5,"CTR","") | O3: =IFERROR(INDEX(Client_Master!$R$2:$R$41,MATCH(C3,Client_Master!$A$2:$A$41,0)),"No KYC record") -> Complete
A4: T0003 | B4: 46267 | C4: C011 | D4: Wire In | E4: 48400 | F4: Switzerland | G4: Customer receipt | H4: =IFERROR(INDEX(Client_Master!$B$2:$B$41,MATCH(C4,Client_Master!$A$2:$A$41,0)),"UNKNOWN CLIENT") -> Coral Reef Gaming Ltd | I4: =IF(LEFT(D4,4)="Cash","Y","N") -> N | J4: =IF(OR(D4="Cash Deposit",D4="Wire In"),"In","Out") -> In | K4: =IF(AND(I4="Y",E4>=Assumptions!$B$6,E4<=Assumptions!$B$5),"Y","N") -> N | L4: =IFERROR(INDEX(Assumptions!$B$22:$B$39,MATCH(F4,Assumptions!$A$22:$A$39,0)),0) -> 0 | M4: =IF(I4="Y",SUMIFS($E$2:$E$114,$C$2:$C$114,C4,$B$2:$B$114,B4,$I$2:$I$114,"Y",$J$2:$J$114,J4),0) -> 0 | N4: =IF(M4>Assumptions!$B$5,"CTR","") | O4: =IFERROR(INDEX(Client_Master!$R$2:$R$41,MATCH(C4,Client_Master!$A$2:$A$41,0)),"No KYC record") -> Complete
A5: T0004 | B5: 46267 | C5: C030 | D5: Wire Out | E5: 54100 | F5: Switzerland | G5: Trade settlement | H5: =IFERROR(INDEX(Client_Master!$B$2:$B$41,MATCH(C5,Client_Master!$A$2:$A$41,0)),"UNKNOWN CLIENT") -> Delta Cloud Systems Pvt Ltd | I5: =IF(LEFT(D5,4)="Cash","Y","N") -> N | J5: =IF(OR(D5="Cash Deposit",D5="Wire In"),"In","Out") -> Out | K5: =IF(AND(I5="Y",E5>=Assumptions!$B$6,E5<=Assumptions!$B$5),"Y","N") -> N | L5: =IFERROR(INDEX(Assumptions!$B$22:$B$39,MATCH(F5,Assumptions!$A$22:$A$39,0)),0) -> 0 | M5: =IF(I5="Y",SUMIFS($E$2:$E$114,$C$2:$C$114,C5,$B$2:$B$114,B5,$I$2:$I$114,"Y",$J$2:$J$114,J5),0) -> 0 | N5: =IF(M5>Assumptions!$B$5,"CTR","") | O5: =IFERROR(INDEX(Client_Master!$R$2:$R$41,MATCH(C5,Client_Master!$A$2:$A$41,0)),"No KYC record") -> Complete
A6: T0005 | B6: 46267 | C6: C032 | D6: Wire In | E6: 28500 | F6: Canada | G6: Customer receipt | H6: =IFERROR(INDEX(Client_Master!$B$2:$B$41,MATCH(C6,Client_Master!$A$2:$A$41,0)),"UNKNOWN CLIENT") -> Anatolia Steel Works AS | I6: =IF(LEFT(D6,4)="Cash","Y","N") -> N | J6: =IF(OR(D6="Cash Deposit",D6="Wire In"),"In","Out") -> In | K6: =IF(AND(I6="Y",E6>=Assumptions!$B$6,E6<=Assumptions!$B$5),"Y","N") -> N | L6: =IFERROR(INDEX(Assumptions!$B$22:$B$39,MATCH(F6,Assumptions!$A$22:$A$39,0)),0) -> 0 | M6: =IF(I6="Y",SUMIFS($E$2:$E$114,$C$2:$C$114,C6,$B$2:$B$114,B6,$I$2:$I$114,"Y",$J$2:$J$114,J6),0) -> 0 | N6: =IF(M6>Assumptions!$B$5,"CTR","") | O6: =IFERROR(INDEX(Client_Master!$R$2:$R$41,MATCH(C6,Client_Master!$A$2:$A$41,0)),"No KYC record") -> Complete
